[2025-10-15 12:56:57 +0500] [364655] [INFO] Starting gunicorn 23.0.0
[2025-10-15 12:56:57 +0500] [364655] [INFO] Listening at: http://127.0.0.1:8000 (364655)
[2025-10-15 12:56:57 +0500] [364655] [INFO] Using worker: sync
[2025-10-15 12:56:57 +0500] [364656] [INFO] Booting worker with pid: 364656
[2025-10-15 12:56:57 +0500] [364656] [ERROR] Exception in worker process
Traceback (most recent call last):
  File "/var/www/clients/client3/web71/home/aidasshbook/venv/lib/python3.11/site-packages/gunicorn/arbiter.py", line 608, in spawn_worker
    worker.init_process()
  File "/var/www/clients/client3/web71/home/aidasshbook/venv/lib/python3.11/site-packages/gunicorn/workers/base.py", line 135, in init_process
    self.load_wsgi()
  File "/var/www/clients/client3/web71/home/aidasshbook/venv/lib/python3.11/site-packages/gunicorn/workers/base.py", line 147, in load_wsgi
    self.wsgi = self.app.wsgi()
                ^^^^^^^^^^^^^^^
  File "/var/www/clients/client3/web71/home/aidasshbook/venv/lib/python3.11/site-packages/gunicorn/app/base.py", line 66, in wsgi
    self.callable = self.load()
                    ^^^^^^^^^^^
  File "/var/www/clients/client3/web71/home/aidasshbook/venv/lib/python3.11/site-packages/gunicorn/app/wsgiapp.py", line 57, in load
    return self.load_wsgiapp()
           ^^^^^^^^^^^^^^^^^^^
  File "/var/www/clients/client3/web71/home/aidasshbook/venv/lib/python3.11/site-packages/gunicorn/app/wsgiapp.py", line 47, in load_wsgiapp
    return util.import_app(self.app_uri)
           ^^^^^^^^^^^^^^^^^^^^^^^^^^^^^
  File "/var/www/clients/client3/web71/home/aidasshbook/venv/lib/python3.11/site-packages/gunicorn/util.py", line 370, in import_app
    mod = importlib.import_module(module)
          ^^^^^^^^^^^^^^^^^^^^^^^^^^^^^^^
  File "/usr/lib/python3.11/importlib/__init__.py", line 126, in import_module
    return _bootstrap._gcd_import(name[level:], package, level)
           ^^^^^^^^^^^^^^^^^^^^^^^^^^^^^^^^^^^^^^^^^^^^^^^^^^^^
  File "<frozen importlib._bootstrap>", line 1206, in _gcd_import
  File "<frozen importlib._bootstrap>", line 1178, in _find_and_load
  File "<frozen importlib._bootstrap>", line 1128, in _find_and_load_unlocked
  File "<frozen importlib._bootstrap>", line 241, in _call_with_frames_removed
  File "<frozen importlib._bootstrap>", line 1206, in _gcd_import
  File "<frozen importlib._bootstrap>", line 1178, in _find_and_load
  File "<frozen importlib._bootstrap>", line 1142, in _find_and_load_unlocked
ModuleNotFoundError: No module named 'main'
[2025-10-15 12:56:57 +0500] [364656] [INFO] Worker exiting (pid: 364656)
[2025-10-15 12:56:57 +0500] [364655] [ERROR] Worker (pid:364656) exited with code 3
[2025-10-15 12:56:57 +0500] [364655] [ERROR] Shutting down: Master
[2025-10-15 12:56:57 +0500] [364655] [ERROR] Reason: Worker failed to boot.
[2025-10-15 13:00:31 +0500] [365496] [INFO] Starting gunicorn 23.0.0
[2025-10-15 13:00:31 +0500] [365496] [INFO] Listening at: http://127.0.0.1:8000 (365496)
[2025-10-15 13:00:31 +0500] [365496] [INFO] Using worker: sync
[2025-10-15 13:00:31 +0500] [365497] [INFO] Booting worker with pid: 365497
[2025-10-15 13:00:31 +0500] [365497] [ERROR] Exception in worker process
Traceback (most recent call last):
  File "/var/www/clients/client3/web71/home/aidasshbook/venv/lib/python3.11/site-packages/gunicorn/arbiter.py", line 608, in spawn_worker
    worker.init_process()
  File "/var/www/clients/client3/web71/home/aidasshbook/venv/lib/python3.11/site-packages/gunicorn/workers/base.py", line 135, in init_process
    self.load_wsgi()
  File "/var/www/clients/client3/web71/home/aidasshbook/venv/lib/python3.11/site-packages/gunicorn/workers/base.py", line 147, in load_wsgi
    self.wsgi = self.app.wsgi()
                ^^^^^^^^^^^^^^^
  File "/var/www/clients/client3/web71/home/aidasshbook/venv/lib/python3.11/site-packages/gunicorn/app/base.py", line 66, in wsgi
    self.callable = self.load()
                    ^^^^^^^^^^^
  File "/var/www/clients/client3/web71/home/aidasshbook/venv/lib/python3.11/site-packages/gunicorn/app/wsgiapp.py", line 57, in load
    return self.load_wsgiapp()
           ^^^^^^^^^^^^^^^^^^^
  File "/var/www/clients/client3/web71/home/aidasshbook/venv/lib/python3.11/site-packages/gunicorn/app/wsgiapp.py", line 47, in load_wsgiapp
    return util.import_app(self.app_uri)
           ^^^^^^^^^^^^^^^^^^^^^^^^^^^^^
  File "/var/www/clients/client3/web71/home/aidasshbook/venv/lib/python3.11/site-packages/gunicorn/util.py", line 370, in import_app
    mod = importlib.import_module(module)
          ^^^^^^^^^^^^^^^^^^^^^^^^^^^^^^^
  File "/usr/lib/python3.11/importlib/__init__.py", line 126, in import_module
    return _bootstrap._gcd_import(name[level:], package, level)
           ^^^^^^^^^^^^^^^^^^^^^^^^^^^^^^^^^^^^^^^^^^^^^^^^^^^^
  File "<frozen importlib._bootstrap>", line 1206, in _gcd_import
  File "<frozen importlib._bootstrap>", line 1178, in _find_and_load
  File "<frozen importlib._bootstrap>", line 1128, in _find_and_load_unlocked
  File "<frozen importlib._bootstrap>", line 241, in _call_with_frames_removed
  File "<frozen importlib._bootstrap>", line 1206, in _gcd_import
  File "<frozen importlib._bootstrap>", line 1178, in _find_and_load
  File "<frozen importlib._bootstrap>", line 1142, in _find_and_load_unlocked
ModuleNotFoundError: No module named 'main'
[2025-10-15 13:00:31 +0500] [365497] [INFO] Worker exiting (pid: 365497)
[2025-10-15 13:00:31 +0500] [365496] [ERROR] Worker (pid:365497) exited with code 3
[2025-10-15 13:00:31 +0500] [365496] [ERROR] Shutting down: Master
[2025-10-15 13:00:31 +0500] [365496] [ERROR] Reason: Worker failed to boot.
